<?xml version="1.0" ?>
<robot xmlns:xacro="http://www.ros.org/wiki/xacro">

  <xacro:macro name="bogie_right" params="">
  <link
    name="BogieR">
    <inertial>
      <origin
        xyz="0.0012451 0.019213 0.059188"
        rpy="0 0 0" />
      <mass
        value="0.2604" />
      <inertia
        ixx="0.00013302"
        ixy="4.4666E-06"
        ixz="-7.651E-06"
        iyy="0.00022904"
        iyz="-2.842E-05"
        izz="0.0001933" />
    </inertial>
    <visual>
      <origin
        xyz="0 0 0"
        rpy="0 0 0" />
      <geometry>
        <mesh
          filename="package://new_spirit_mars/meshes/BogieR.STL" />
      </geometry>
      <material
        name="">
        <color
          rgba="1 1 1 1" />
      </material>
    </visual>
    <collision>
      <origin
        xyz="0 0 0"
        rpy="0 0 0" />
      <geometry>
        <mesh
          filename="package://new_spirit_mars/meshes/BogieR.STL" />
      </geometry>
    </collision>
  </link>
  <joint
      name="RockerR_BogieR"
      type="revolute">
      <origin
        xyz="0.180999685953231 0.061999892425969 0.00269999999999999"
        rpy="0 0 0" />
      <parent
        link="RockerR" />
      <child
        link="BogieR" />
      <axis
        xyz="0 0 -1"
        />
        <limit lower="${suspension_arm_B_L_limit_lower}" upper="${suspension_arm_B_L_limit_upper}" effort="${suspension_effort}" velocity="${suspension_speed}"/>
        <joint_properties damping="${suspension_damping}" friction="${suspension_friction}"/>
    </joint>

<transmission name="BogieR">
<type>transmission_interface/SimpleTransmission</type>
<joint name="RockerR_BogieR">
<hardwareInterface>hardware_interface/EffortJointInterface</hardwareInterface>
</joint>
<actuator name="BogieRMotor">
<hardwareInterface>hardware_interface/EffortJointInterface</hardwareInterface>
<mechanicalReduction>1</mechanicalReduction>
</actuator>
</transmission>

  <link
    name="MidWheelR">
    <inertial>
      <origin
        xyz="3.1987E-07 1.6968E-07 -0.040318"
        rpy="0 0 0" />
      <mass
        value="0.11466" />
      <inertia
        ixx="0.0002563"
        ixy="6.731E-09"
        ixz="-7.6234E-10"
        iyy="0.0002563"
        iyz="9.3179E-10"
        izz="0.00032223" />
    </inertial>
    <visual>
      <origin
        xyz="0 0 0"
        rpy="0 0 0" />
      <geometry>
        <mesh
          filename="package://new_spirit_mars/meshes/MidWheelR.STL" />
      </geometry>
      <material
        name="">
        <color
          rgba="0 0 0 1" />
      </material>
    </visual>
    <collision>
      <origin
        xyz="0 0 0"
        rpy="0 0 0" />
      <geometry>
        <mesh
          filename="package://new_spirit_mars/meshes/MidWheelR.STL" />
      </geometry>
    </collision>
  </link>
  <joint
    name="BogieR_MWR"
    type="continuous">
    <origin
      xyz="-0.12382 0.054495 0.1494"
      rpy="0 0 0.61828" />
    <parent
      link="BogieR" />
    <child
      link="MidWheelR" />
    <axis
      xyz="0 0 -1" />
  </joint>
  <link
    name="RearSteeringR">
    <inertial>
      <origin
        xyz="0.013524 0.016635 -0.075591"
        rpy="0 0 0" />
      <mass
        value="0.12473" />
      <inertia
        ixx="0.00018921"
        ixy="-4.6317E-05"
        ixz="-3.6575E-05"
        iyy="0.00018034"
        iyz="-3.2316E-05"
        izz="0.00012966" />
    </inertial>
    <visual>
      <origin
        xyz="0 0 0"
        rpy="0 0 0" />
      <geometry>
        <mesh
          filename="package://new_spirit_mars/meshes/RearSteeringR.STL" />
      </geometry>
      <material
        name="">
        <color
          rgba="1 1 1 1" />
      </material>
    </visual>
    <collision>
      <origin
        xyz="0 0 0"
        rpy="0 0 0" />
      <geometry>
        <mesh
          filename="package://new_spirit_mars/meshes/RearSteeringR.STL" />
      </geometry>
    </collision>
  </link>
  <joint
      name="BogieR_RSR"
      type="revolute">
      <origin
        xyz="0.15073 0.017246 0.070331"
        rpy="1.6092 2.47694 0.35607" />
      <parent
        link="BogieR" />
      <child
        link="RearSteeringR" />
      <axis
        xyz="0 0 -1" />

      <limit
        lower="0"
        upper="0"
        effort="0"
        velocity="0" />
    </joint>
  <link
    name="WheelRSR">
    <inertial>
      <origin
        xyz="3.5294E-07 1.4496E-07 -0.040318"
        rpy="0 0 0" />
      <mass
        value="0.11466" />
      <inertia
        ixx="0.0002563"
        ixy="-8.238E-10"
        ixz="-1.2711E-09"
        iyy="0.0002563"
        iyz="3.7072E-10"
        izz="0.00032223" />
    </inertial>
    <visual>
      <origin
        xyz="0 0 0"
        rpy="0 0 0" />
      <geometry>
        <mesh
          filename="package://new_spirit_mars/meshes/WheelRSR.STL" />
      </geometry>
      <material
        name="">
        <color
          rgba="0 0 0 1" />
      </material>
    </visual>
    <collision>
      <origin
        xyz="0 0 0"
        rpy="0 0 0" />
      <geometry>
        <mesh
          filename="package://new_spirit_mars/meshes/WheelRSR.STL" />
      </geometry>
    </collision>
  </link>
  <joint
    name="RSR_WheelRSR"
    type="continuous">
    <origin
      xyz="-0.032911 -0.036303 -0.13085"
      rpy="-1.5708 0.83047 2.4078" />
    <parent
      link="RearSteeringR" />
    <child
      link="WheelRSR" />
    <axis
      xyz="0 0 -1" />
  </joint>
  </xacro:macro>
  </robot>
