<?xml version="1.0" encoding="utf-8"?>
<!-- This URDF was automatically created by SolidWorks to URDF Exporter! Originally created by Stephen Brawner (brawner@gmail.com) 
     Commit Version: 1.5.1-0-g916b5db  Build Version: 1.5.7152.31018
     For more information, please see http://wiki.ros.org/sw_urdf_exporter -->
<robot
  name="new_spirit_mars">
  <link
    name="RoverChassis">
    <inertial>
      <origin
        xyz="0.0093614 -9.9176E-05 0.050783"
        rpy="0 0 0" />
      <mass
        value="2.5513" />
      <inertia
        ixx="0.0059302"
        ixy="-2.3769E-06"
        ixz="8.4014E-05"
        iyy="0.013"
        iyz="-1.4168E-05"
        izz="0.017599" />
    </inertial>
    <visual>
      <origin
        xyz="0 0 0"
        rpy="0 0 0" />
      <geometry>
        <mesh
          filename="package://new_spirit_mars/meshes/RoverChassis.STL" />
      </geometry>
      <material
        name="">
        <color
          rgba="0.094118 0 0.20784 1" />
      </material>
    </visual>
    <collision>
      <origin
        xyz="0 0 0"
        rpy="0 0 0" />
      <geometry>
        <mesh
          filename="package://new_spirit_mars/meshes/RoverChassis.STL" />
      </geometry>
    </collision>
  </link>
  <link
    name="MastArm">
    <inertial>
      <origin
        xyz="-0.00021473 0.051397 -0.00073642"
        rpy="0 0 0" />
      <mass
        value="0.040089" />
      <inertia
        ixx="8.1919E-05"
        ixy="1.6871E-09"
        ixz="5.5106E-10"
        iyy="5.8703E-06"
        iyz="-5.4206E-07"
        izz="8.6546E-05" />
    </inertial>
    <visual>
      <origin
        xyz="0 0 0"
        rpy="0 0 0" />
      <geometry>
        <mesh
          filename="package://new_spirit_mars/meshes/MastArm.STL" />
      </geometry>
      <material
        name="">
        <color
          rgba="1 1 1 1" />
      </material>
    </visual>
    <collision>
      <origin
        xyz="0 0 0"
        rpy="0 0 0" />
      <geometry>
        <mesh
          filename="package://new_spirit_mars/meshes/MastArm.STL" />
      </geometry>
    </collision>
  </link>
  <joint
    name="RoverChassis_Mast"
    type="revolute">
    <origin
      xyz="0.13149 -0.053006 0.14751"
      rpy="1.5708 -0.0056094 2.3562" />
    <parent
      link="RoverChassis" />
    <child
      link="MastArm" />
    <axis
      xyz="0 0 -1" />
    <limit
      lower="0"
      upper="0"
      effort="0"
      velocity="0" />
  </joint>
  <link
    name="MastHead">
    <inertial>
      <origin
        xyz="-0.0013429 0.00089648 -0.022625"
        rpy="0 0 0" />
      <mass
        value="0.037642" />
      <inertia
        ixx="5.6108E-05"
        ixy="-1.2333E-09"
        ixz="7.2038E-08"
        iyy="1.6403E-05"
        iyz="8.3386E-08"
        izz="4.6655E-05" />
    </inertial>
    <visual>
      <origin
        xyz="0 0 0"
        rpy="0 0 0" />
      <geometry>
        <mesh
          filename="package://new_spirit_mars/meshes/MastHead.STL" />
      </geometry>
      <material
        name="">
        <color
          rgba="1 1 1 1" />
      </material>
    </visual>
    <collision>
      <origin
        xyz="0 0 0"
        rpy="0 0 0" />
      <geometry>
        <mesh
          filename="package://new_spirit_mars/meshes/MastHead.STL" />
      </geometry>
    </collision>
  </link>
  <joint
    name="MastArm_MastHead"
    type="revolute">
    <origin
      xyz="0.00029854 0.15045 0.004"
      rpy="1.5708 0.79479 0" />
    <parent
      link="MastArm" />
    <child
      link="MastHead" />
    <axis
      xyz="0 0 1" />
    <limit
      lower="0"
      upper="0"
      effort="0"
      velocity="0" />
  </joint>
  <link
    name="Arm">
    <inertial>
      <origin
        xyz="-0.00013011 0.057834 0.0017688"
        rpy="0 0 0" />
      <mass
        value="0.065681" />
      <inertia
        ixx="0.00010918"
        ixy="-1.6866E-09"
        ixz="2.4327E-10"
        iyy="9.2922E-06"
        iyz="2.444E-07"
        izz="0.00011408" />
    </inertial>
    <visual>
      <origin
        xyz="0 0 0"
        rpy="0 0 0" />
      <geometry>
        <mesh
          filename="package://new_spirit_mars/meshes/Arm.STL" />
      </geometry>
      <material
        name="">
        <color
          rgba="1 1 1 1" />
      </material>
    </visual>
    <collision>
      <origin
        xyz="0 0 0"
        rpy="0 0 0" />
      <geometry>
        <mesh
          filename="package://new_spirit_mars/meshes/Arm.STL" />
      </geometry>
    </collision>
  </link>
  <joint
    name="Chassis_Arm"
    type="revolute">
    <origin
      xyz="0.253051748698285 0.0704529943574704 0.0609913956856037"
      rpy="1.5707963267949 -0.130632744206875 -3.14159265358979" />
    <parent
      link="RoverChassis" />
    <child
      link="Arm" />
    <axis
      xyz="0 0 1" />
    <limit
      lower="0"
      upper="0"
      effort="0"
      velocity="0" />
  </joint>
  <link
    name="Arm2">
    <inertial>
      <origin
        xyz="0.0014503 0.03926 0.016609"
        rpy="0 0 0" />
      <mass
        value="0.051274" />
      <inertia
        ixx="5.5647E-05"
        ixy="-1.4498E-06"
        ixz="-8.8093E-09"
        iyy="9.5179E-06"
        iyz="-2.9315E-07"
        izz="5.9312E-05" />
    </inertial>
    <visual>
      <origin
        xyz="0 0 0"
        rpy="0 0 0" />
      <geometry>
        <mesh
          filename="package://new_spirit_mars/meshes/Arm2.STL" />
      </geometry>
      <material
        name="">
        <color
          rgba="1 1 1 1" />
      </material>
    </visual>
    <collision>
      <origin
        xyz="0 0 0"
        rpy="0 0 0" />
      <geometry>
        <mesh
          filename="package://new_spirit_mars/meshes/Arm2.STL" />
      </geometry>
    </collision>
  </link>
  <joint
    name="Arm_Arm2"
    type="revolute">
    <origin
      xyz="0 0.11924 0"
      rpy="-3.1416 0 1.5708" />
    <parent
      link="Arm" />
    <child
      link="Arm2" />
    <axis
      xyz="0 0 -1" />
    <limit
      lower="0"
      upper="0"
      effort="0"
      velocity="0" />
  </joint>
  <link
    name="Arm3">
    <inertial>
      <origin
        xyz="0.0050459 -0.0052647 -0.017841"
        rpy="0 0 0" />
      <mass
        value="0.016829" />
      <inertia
        ixx="3.9904E-06"
        ixy="-4.0705E-09"
        ixz="-1.1789E-08"
        iyy="5.1228E-06"
        iyz="-5.8731E-07"
        izz="2.6647E-06" />
    </inertial>
    <visual>
      <origin
        xyz="0 0 0"
        rpy="0 0 0" />
      <geometry>
        <mesh
          filename="package://new_spirit_mars/meshes/Arm3.STL" />
      </geometry>
      <material
        name="">
        <color
          rgba="1 1 1 1" />
      </material>
    </visual>
    <collision>
      <origin
        xyz="0 0 0"
        rpy="0 0 0" />
      <geometry>
        <mesh
          filename="package://new_spirit_mars/meshes/Arm3.STL" />
      </geometry>
    </collision>
  </link>
  <joint
    name="Arm2_Arm3"
    type="revolute">
    <origin
      xyz="-0.00231376659955707 0.0917099175886816 0.0167"
      rpy="1.5707963267949 0.0495995429747262 -0.0298514149555396" />
    <parent
      link="Arm2" />
    <child
      link="Arm3" />
    <axis
      xyz="0 0 1" />
    <limit
      lower="0"
      upper="0"
      effort="0"
      velocity="0" />
  </joint>
  <link
    name="EFE">
    <inertial>
      <origin
        xyz="0.035646 -0.03828 0.00179"
        rpy="0 0 0" />
      <mass
        value="0.035617" />
      <inertia
        ixx="7.9239E-06"
        ixy="5.0355E-06"
        ixz="-9.5166E-07"
        iyy="8.5973E-06"
        iyz="1.1051E-06"
        izz="1.1584E-05" />
    </inertial>
    <visual>
      <origin
        xyz="0 0 0"
        rpy="0 0 0" />
      <geometry>
        <mesh
          filename="package://new_spirit_mars/meshes/EFE.STL" />
      </geometry>
      <material
        name="">
        <color
          rgba="1 1 1 1" />
      </material>
    </visual>
    <collision>
      <origin
        xyz="0 0 0"
        rpy="0 0 0" />
      <geometry>
        <mesh
          filename="package://new_spirit_mars/meshes/EFE.STL" />
      </geometry>
    </collision>
  </link>
  <joint
    name="Arm3_EFE"
    type="revolute">
    <origin
      xyz="0.005 -0.014 -0.0279999999985077"
      rpy="-1.5707963267949 0 0" />
    <parent
      link="Arm3" />
    <child
      link="EFE" />
    <axis
      xyz="0 0 -1" />
    <limit
      lower="0"
      upper="0"
      effort="0"
      velocity="0" />
  </joint>
  <link
    name="Rocker1">
    <inertial>
      <origin
        xyz="-0.050037 -0.023664 0.036781"
        rpy="0 0 0" />
      <mass
        value="0.29452" />
      <inertia
        ixx="0.00010836"
        ixy="-1.9106E-06"
        ixz="4.7399E-05"
        iyy="0.00035209"
        iyz="2.0093E-05"
        izz="0.00038621" />
    </inertial>
    <visual>
      <origin
        xyz="0 0 0"
        rpy="0 0 0" />
      <geometry>
        <mesh
          filename="package://new_spirit_mars/meshes/Rocker1.STL" />
      </geometry>
      <material
        name="">
        <color
          rgba="1 1 1 1" />
      </material>
    </visual>
    <collision>
      <origin
        xyz="0 0 0"
        rpy="0 0 0" />
      <geometry>
        <mesh
          filename="package://new_spirit_mars/meshes/Rocker1.STL" />
      </geometry>
    </collision>
  </link>
  <joint
    name="Chassis_Rocker1"
    type="continuous">
    <origin
      xyz="0.073 0.1572 0.0527"
      rpy="1.5708 -0.073241 -3.1416" />
    <parent
      link="RoverChassis" />
    <child
      link="Rocker1" />
    <axis
      xyz="0 0 -1" />
    <limit
      lower="0"
      upper="0"
      effort="0"
      velocity="0" />
  </joint>
  <link
    name="Bogie1">
    <inertial>
      <origin
        xyz="0.017556 0.0078829 0.040966"
        rpy="0 0 0" />
      <mass
        value="0.28915" />
      <inertia
        ixx="0.0002275"
        ixy="2.9536E-05"
        ixz="-2.5079E-05"
        iyy="0.00014962"
        iyz="-1.5329E-05"
        izz="0.00020374" />
    </inertial>
    <visual>
      <origin
        xyz="0 0 0"
        rpy="0 0 0" />
      <geometry>
        <mesh
          filename="package://new_spirit_mars/meshes/Bogie1.STL" />
      </geometry>
      <material
        name="">
        <color
          rgba="1 1 1 1" />
      </material>
    </visual>
    <collision>
      <origin
        xyz="0 0 0"
        rpy="0 0 0" />
      <geometry>
        <mesh
          filename="package://new_spirit_mars/meshes/Bogie1.STL" />
      </geometry>
    </collision>
  </link>
  <joint
    name="Rocker1_Bogie1"
    type="continuous">
    <origin
      xyz="0.180999685953205 -0.0619998924263396 0.0226999999994359"
      rpy="0 0 -1.5707963267949" />
    <parent
      link="Rocker1" />
    <child
      link="Bogie1" />
    <axis
      xyz="0 0 1" />
    <limit
      lower="0"
      upper="0"
      effort="0"
      velocity="0" />
  </joint>
  <link
    name="MidWheel1">
    <inertial>
      <origin
        xyz="-1.00097760736412E-05 -1.7549813208631E-05 -0.0391473582429716"
        rpy="0 0 0" />
      <mass
        value="0.121635456546398" />
      <inertia
        ixx="0.000257155753097487"
        ixy="4.92178958474824E-09"
        ixz="4.65649359439084E-10"
        iyy="0.00025715474822993"
        iyz="-2.18199010808682E-09"
        izz="0.00032279802977436" />
    </inertial>
    <visual>
      <origin
        xyz="0 0 0"
        rpy="0 0 0" />
      <geometry>
        <mesh
          filename="package://new_spirit_mars/meshes/MidWheel1.STL" />
      </geometry>
      <material
        name="">
        <color
          rgba="0.792156862745098 0.819607843137255 0.933333333333333 1" />
      </material>
    </visual>
    <collision>
      <origin
        xyz="0 0 0"
        rpy="0 0 0" />
      <geometry>
        <mesh
          filename="package://new_spirit_mars/meshes/MidWheel1.STL" />
      </geometry>
    </collision>
  </link>
  <joint
    name="Bogie1_MW1"
    type="continuous">
    <origin
      xyz="0.0869482106774486 -0.103155541790304 0.130899998852721"
      rpy="0 0 0.865693911327975" />
    <parent
      link="Bogie1" />
    <child
      link="MidWheel1" />
    <axis
      xyz="0 0 1" />
  </joint>
  <link
    name="RearSteering1">
    <inertial>
      <origin
        xyz="-0.00422334190750609 -0.0199529774661564 -0.0790388602924965"
        rpy="0 0 0" />
      <mass
        value="0.142145566427233" />
      <inertia
        ixx="0.000234346128308017"
        ixy="-1.40951343398391E-05"
        ixz="2.32468332009533E-06"
        iyy="0.000147571755564679"
        iyz="4.87561458509139E-05"
        izz="0.000131998625605861" />
    </inertial>
    <visual>
      <origin
        xyz="0 0 0"
        rpy="0 0 0" />
      <geometry>
        <mesh
          filename="package://new_spirit_mars/meshes/RearSteering1.STL" />
      </geometry>
      <material
        name="">
        <color
          rgba="0.498039215686275 0.498039215686275 0.498039215686275 1" />
      </material>
    </visual>
    <collision>
      <origin
        xyz="0 0 0"
        rpy="0 0 0" />
      <geometry>
        <mesh
          filename="package://new_spirit_mars/meshes/RearSteering1.STL" />
      </geometry>
    </collision>
  </link>
  <joint
    name="Bogie1_RS1"
    type="revolute">
    <origin
      xyz="-0.0257730882832044 0.150552819672626 0.0503310877983017"
      rpy="-1.59518110347134 0.192038010266344 1.51476049572154" />
    <parent
      link="Bogie1" />
    <child
      link="RearSteering1" />
    <axis
      xyz="0 0 -1" />
    <limit
      lower="0"
      upper="0"
      effort="0"
      velocity="0" />
  </joint>
  <link
    name="WheelRS1">
    <inertial>
      <origin
        xyz="3.35987398888959E-06 -9.91969171384999E-06 -0.0391475708881186"
        rpy="0 0 0" />
      <mass
        value="0.121634395963816" />
      <inertia
        ixx="0.000257161144220671"
        ixy="2.1354818745808E-09"
        ixz="-6.7876992009368E-10"
        iyy="0.000257148215998535"
        iyz="-2.76349276868951E-09"
        izz="0.000322797785838331" />
    </inertial>
    <visual>
      <origin
        xyz="0 0 0"
        rpy="0 0 0" />
      <geometry>
        <mesh
          filename="package://new_spirit_mars/meshes/WheelRS1.STL" />
      </geometry>
      <material
        name="">
        <color
          rgba="0.792156862745098 0.819607843137255 0.933333333333333 1" />
      </material>
    </visual>
    <collision>
      <origin
        xyz="0 0 0"
        rpy="0 0 0" />
      <geometry>
        <mesh
          filename="package://new_spirit_mars/meshes/WheelRS1.STL" />
      </geometry>
    </collision>
  </link>
  <joint
    name="RS1_WHeelRS1"
    type="continuous">
    <origin
      xyz="0.0081708 0.049328 -0.13087"
      rpy="1.5708 -1.4045 2.9805" />
    <parent
      link="RearSteering1" />
    <child
      link="WheelRS1" />
    <axis
      xyz="0 0 -1" />
  </joint>
  <link
    name="FrontSteering1">
    <inertial>
      <origin
        xyz="0.00198903207560586 0.0202978331365523 -0.0790455109517943"
        rpy="0 0 0" />
      <mass
        value="0.142148375854442" />
      <inertia
        ixx="0.000236376652504394"
        ixy="-4.17060009261255E-06"
        ixz="3.10445945005631E-06"
        iyy="0.000145531559669667"
        iyz="-4.87125877429576E-05"
        izz="0.000132009378586939" />
    </inertial>
    <visual>
      <origin
        xyz="0 0 0"
        rpy="0 0 0" />
      <geometry>
        <mesh
          filename="package://new_spirit_mars/meshes/FrontSteering1.STL" />
      </geometry>
      <material
        name="">
        <color
          rgba="1 1 1 1" />
      </material>
    </visual>
    <collision>
      <origin
        xyz="0 0 0"
        rpy="0 0 0" />
      <geometry>
        <mesh
          filename="package://new_spirit_mars/meshes/FrontSteering1.STL" />
      </geometry>
    </collision>
  </link>
  <joint
    name="Rocker1_FS1"
    type="revolute">
    <origin
      xyz="-0.211672796800495 -0.0289412092543823 0.0760067485203597"
      rpy="1.56801817837417 -0.126468861634388 -3.14123445081466" />
    <parent
      link="Rocker1" />
    <child
      link="FrontSteering1" />
    <axis
      xyz="0 0 1" />
    <limit
      lower="0"
      upper="0"
      effort="0"
      velocity="0" />
  </joint>
  <link
    name="WheelFS1">
    <inertial>
      <origin
        xyz="2.04926562190622E-05 -5.0253471550743E-08 -0.0391469827747634"
        rpy="0 0 0" />
      <mass
        value="0.121634363451582" />
      <inertia
        ixx="0.000257160590216909"
        ixy="2.53636887261353E-09"
        ixz="-8.84649293601917E-12"
        iyy="0.000257147953642745"
        iyz="-2.8414083982703E-09"
        izz="0.000322797808936208" />
    </inertial>
    <visual>
      <origin
        xyz="0 0 0"
        rpy="0 0 0" />
      <geometry>
        <mesh
          filename="package://new_spirit_mars/meshes/WheelFS1.STL" />
      </geometry>
      <material
        name="">
        <color
          rgba="0.792156862745098 0.819607843137255 0.933333333333333 1" />
      </material>
    </visual>
    <collision>
      <origin
        xyz="0 0 0"
        rpy="0 0 0" />
      <geometry>
        <mesh
          filename="package://new_spirit_mars/meshes/WheelFS1.STL" />
      </geometry>
    </collision>
  </link>
  <joint
    name="FS1_WheelFS1"
    type="continuous">
    <origin
      xyz="-0.00253456678339498 -0.0499357397038631 -0.131194605457668"
      rpy="1.57079632679491 -1.33800948212218 -0.049790288634686" />
    <parent
      link="FrontSteering1" />
    <child
      link="WheelFS1" />
    <axis
      xyz="0 0 1" />
  </joint>
  <link
    name="Rocker2">
    <inertial>
      <origin
        xyz="-0.050032 0.023664 0.036785"
        rpy="0 0 0" />
      <mass
        value="0.29452" />
      <inertia
        ixx="0.00010834"
        ixy="1.9104E-06"
        ixz="4.7402E-05"
        iyy="0.00035209"
        iyz="-2.0093E-05"
        izz="0.00038622" />
    </inertial>
    <visual>
      <origin
        xyz="0 0 0"
        rpy="1.5707 0 0" />
      <geometry>
        <mesh
          filename="package://new_spirit_mars/meshes/Rocker2.STL" />
      </geometry>
      <material
        name="">
        <color
          rgba="1 1 1 1" />
      </material>
    </visual>
    <collision>
      <origin
        xyz="0 0 0"
        rpy="0 0 0" />
      <geometry>
        <mesh
          filename="package://new_spirit_mars/meshes/Rocker2.STL" />
      </geometry>
    </collision>
  </link>
  <joint
    name="Chasiss_Rocker2"
    type="continuous">
    <origin
      xyz="0.073 -0.1572 0.0527"
      rpy="-1.5708 0.073342 -3.1416" />
    <parent
      link="RoverChassis" />
    <child
      link="Rocker2" />
    <axis
      xyz="0 0 -1" />
    <limit
      lower="0"
      upper="0"
      effort="0"
      velocity="0" />
  </joint>
  <link
    name="Bogie2">
    <inertial>
      <origin
        xyz="0.0096552 0.016648 0.060952"
        rpy="0 0 0" />
      <mass
        value="0.28916" />
      <inertia
        ixx="0.00015652"
        ixy="3.69E-05"
        ixz="-1.7843E-05"
        iyy="0.00022061"
        iyz="-2.3369E-05"
        izz="0.00020375" />
    </inertial>
    <visual>
      <origin
        xyz="0 0 0"
        rpy="0 0 0" />
      <geometry>
        <mesh
          filename="package://new_spirit_mars/meshes/Bogie2.STL" />
      </geometry>
      <material
        name="">
        <color
          rgba="0.89804 0.91765 0.92941 1" />
      </material>
    </visual>
    <collision>
      <origin
        xyz="0 0 0"
        rpy="0 0 0" />
      <geometry>
        <mesh
          filename="package://new_spirit_mars/meshes/Bogie2.STL" />
      </geometry>
    </collision>
  </link>
  <joint
    name="Rocker2_Bogie2"
    type="continuous">
    <origin
      xyz="0.180999685955288 0.0619998924230409 0.00270000000285972"
      rpy="0 0 0" />
    <parent
      link="Rocker2" />
    <child
      link="Bogie2" />
    <axis
      xyz="0 0 -1" />
    <limit
      lower="0"
      upper="0"
      effort="0"
      velocity="0" />
  </joint>
  <link
    name="MidWheel2">
    <inertial>
      <origin
        xyz="2.1358150938313E-05 -1.56490550163452E-05 -0.0386688982970209"
        rpy="0 0 0" />
      <mass
        value="0.125822865739578" />
      <inertia
        ixx="0.000258026205662039"
        ixy="-2.74904979008728E-09"
        ixz="-1.45058477661596E-09"
        iyy="0.000258013206444936"
        iyz="1.05758605400458E-09"
        izz="0.000322795683780587" />
    </inertial>
    <visual>
      <origin
        xyz="0 0 0"
        rpy="0 0 0" />
      <geometry>
        <mesh
          filename="package://new_spirit_mars/meshes/MidWheel2.STL" />
      </geometry>
      <material
        name="">
        <color
          rgba="0.898039215686275 0.917647058823529 0.929411764705882 1" />
      </material>
    </visual>
    <collision>
      <origin
        xyz="0 0 0"
        rpy="0 0 0" />
      <geometry>
        <mesh
          filename="package://new_spirit_mars/meshes/MidWheel2.STL" />
      </geometry>
    </collision>
  </link>
  <joint
    name="Bogie2_MW2"
    type="continuous">
    <origin
      xyz="-0.0939371315502092 0.0973703592993591 0.149400000000058"
      rpy="0 0 -0.302685933437432" />
    <parent
      link="Bogie2" />
    <child
      link="MidWheel2" />
    <axis
      xyz="0 0 1" />
  </joint>
  <link
    name="RearSteering2">
    <inertial>
      <origin
        xyz="0.0092945588904586 0.0181820861520627 -0.0790354331432768"
        rpy="0 0 0" />
      <mass
        value="0.142141326995898" />
      <inertia
        ixx="0.000213729236438896"
        ixy="-3.952277731969E-05"
        ixz="-2.88856062629526E-05"
        iyy="0.000168175173433327"
        iyz="-3.93403173720442E-05"
        izz="0.000131991707849784" />
    </inertial>
    <visual>
      <origin
        xyz="0 0 0"
        rpy="0 0 0" />
      <geometry>
        <mesh
          filename="package://new_spirit_mars/meshes/RearSteering2.STL" />
      </geometry>
      <material
        name="">
        <color
          rgba="0.792156862745098 0.819607843137255 0.933333333333333 1" />
      </material>
    </visual>
    <collision>
      <origin
        xyz="0 0 0"
        rpy="0 0 0" />
      <geometry>
        <mesh
          filename="package://new_spirit_mars/meshes/RearSteering2.STL" />
      </geometry>
    </collision>
  </link>
  <joint
    name="Bogie2_RS2"
    type="revolute">
    <origin
      xyz="0.14709247763711 -0.0411607389706367 0.070331086997081"
      rpy="1.59902656395361 -0.558724110595196 -0.0668908914708698" />
    <parent
      link="Bogie2" />
    <child
      link="RearSteering2" />
    <axis
      xyz="0 0 1" />
    <limit
      lower="0"
      upper="0"
      effort="0"
      velocity="0" />
  </joint>
  <link
    name="WheelRS2">
    <inertial>
      <origin
        xyz="-5.48896118138242E-06 1.43610157684049E-05 -0.0386689061615327"
        rpy="0 0 0" />
      <mass
        value="0.125823228579159" />
      <inertia
        ixx="0.000258029063456796"
        ixy="4.31986102568717E-09"
        ixz="-2.24912670829532E-09"
        iyy="0.00025801309264078"
        iyz="8.32756899534465E-10"
        izz="0.000322796409798318" />
    </inertial>
    <visual>
      <origin
        xyz="0 0 0"
        rpy="0 0 0" />
      <geometry>
        <mesh
          filename="package://new_spirit_mars/meshes/WheelRS2.STL" />
      </geometry>
      <material
        name="">
        <color
          rgba="0.898039215686275 0.917647058823529 0.929411764705882 1" />
      </material>
    </visual>
    <collision>
      <origin
        xyz="0 0 0"
        rpy="0 0 0" />
      <geometry>
        <mesh
          filename="package://new_spirit_mars/meshes/WheelRS2.STL" />
      </geometry>
    </collision>
  </link>
  <joint
    name="RS2_WheelRS2"
    type="continuous">
    <origin
      xyz="-0.024177 -0.04262 -0.13104"
      rpy="1.5708 -1.5023 -0.52001" />
    <parent
      link="RearSteering2" />
    <child
      link="WheelRS2" />
    <axis
      xyz="0 0 1" />
  </joint>
  <link
    name="FrontSteering2">
    <inertial>
      <origin
        xyz="0.0120385311622508 -0.0164642596401307 -0.0790275004579461"
        rpy="0 0 0" />
      <mass
        value="0.14214442284229" />
      <inertia
        ixx="0.000209195778059599"
        ixy="4.18029723765835E-05"
        ixz="-2.21170591370971E-05"
        iyy="0.000172702162395656"
        iyz="4.35069516267105E-05"
        izz="0.000132000981095209" />
    </inertial>
    <visual>
      <origin
        xyz="0 0 0"
        rpy="0 0 0" />
      <geometry>
        <mesh
          filename="package://new_spirit_mars/meshes/FrontSteering2.STL" />
      </geometry>
      <material
        name="">
        <color
          rgba="0.792156862745098 0.819607843137255 0.933333333333333 1" />
      </material>
    </visual>
    <collision>
      <origin
        xyz="0 0 0"
        rpy="0 0 0" />
      <geometry>
        <mesh
          filename="package://new_spirit_mars/meshes/FrontSteering2.STL" />
      </geometry>
    </collision>
  </link>
  <joint
    name="Rocker2_FS2"
    type="revolute">
    <origin
      xyz="-0.21167 0.028941 0.076007"
      rpy="-1.5674 -0.62594 3.1396" />
    <parent
      link="Rocker2" />
    <child
      link="FrontSteering2" />
    <axis
      xyz="0 0 1" />
    <limit
      lower="0"
      upper="0"
      effort="0"
      velocity="0" />
  </joint>
  <link
    name="WheelsFS2">
    <inertial>
      <origin
        xyz="-2.3871814258114E-05 -1.02232363739518E-05 -0.0386682194061028"
        rpy="0 0 0" />
      <mass
        value="0.125823334364886" />
      <inertia
        ixx="0.000258028039075968"
        ixy="6.58567022185992E-09"
        ixz="-9.51957485967972E-10"
        iyy="0.000258028748622919"
        iyz="5.17285642417056E-10"
        izz="0.000322800145224384" />
    </inertial>
    <visual>
      <origin
        xyz="0 0 0"
        rpy="0 0 0" />
      <geometry>
        <mesh
          filename="package://new_spirit_mars/meshes/WheelsFS2.STL" />
      </geometry>
      <material
        name="">
        <color
          rgba="0.898039215686275 0.917647058823529 0.929411764705882 1" />
      </material>
    </visual>
    <collision>
      <origin
        xyz="0 0 0"
        rpy="0 0 0" />
      <geometry>
        <mesh
          filename="package://new_spirit_mars/meshes/WheelsFS2.STL" />
      </geometry>
    </collision>
  </link>
  <joint
    name="FS2_WheelsFS2"
    type="continuous">
    <origin
      xyz="-0.027711 0.041619 -0.13106"
      rpy="1.5708 0.70491 -2.558" />
    <parent
      link="FrontSteering2" />
    <child
      link="WheelsFS2" />
    <axis
      xyz="0 0 1" />
  </joint>
</robot>
